<?xml version="1.0" ?>
<!-- =================================================================================== -->
<!-- |    This document was autogenerated by xacro from /home/vikram/micromouse_ws/src/micromouse_description/urdf/micromouse.urdf.xacro | -->
<!-- |    EDITING THIS FILE BY HAND IS NOT RECOMMENDED                                 | -->
<!-- =================================================================================== -->
<robot name="micromouse">
  <!-- ========= Base Link ========= -->
  <link name="base_link">
    <visual>
      <geometry>
        <box size="0.12 0.1 0.04"/>
      </geometry>
      <material name="Blue"/>
    </visual>
    <collision>
      <geometry>
        <box size="0.12 0.1 0.04"/>
      </geometry>
    </collision>
    <inertial>
      <mass value="0.5"/>
      <inertia ixx="0.001" iyy="0.001" izz="0.001"/>
    </inertial>
  </link>
  <link name="wheel_left">
    <visual>
      <geometry>
        <cylinder length="0.02" radius="0.03"/>
      </geometry>
      <material name="Black"/>
    </visual>
    <collision>
      <geometry>
        <cylinder length="0.02" radius="0.03"/>
      </geometry>
    </collision>
    <inertial>
      <mass value="0.05"/>
      <inertia ixx="0.0001" iyy="0.0001" izz="0.0001"/>
    </inertial>
  </link>
  <joint name="wheel_left_joint" type="continuous">
    <parent link="base_link"/>
    <child link="wheel_left"/>
    <origin rpy="0 0 0" xyz="0 0.04 -0.02"/>
    <axis xyz="0 1 0"/>
  </joint>
  <link name="wheel_right">
    <visual>
      <geometry>
        <cylinder length="0.02" radius="0.03"/>
      </geometry>
      <material name="Black"/>
    </visual>
    <collision>
      <geometry>
        <cylinder length="0.02" radius="0.03"/>
      </geometry>
    </collision>
    <inertial>
      <mass value="0.05"/>
      <inertia ixx="0.0001" iyy="0.0001" izz="0.0001"/>
    </inertial>
  </link>
  <joint name="wheel_right_joint" type="continuous">
    <parent link="base_link"/>
    <child link="wheel_right"/>
    <origin rpy="0 0 0" xyz="0 -0.04 -0.02"/>
    <axis xyz="0 1 0"/>
  </joint>
  <link name="ir_front">
    <visual>
      <geometry>
        <cylinder length="0.02" radius="0.005"/>
      </geometry>
      <material name="Red"/>
    </visual>
    <collision>
      <geometry>
        <cylinder length="0.02" radius="0.005"/>
      </geometry>
    </collision>
  </link>
  <joint name="ir_front_joint" type="fixed">
    <parent link="base_link"/>
    <child link="ir_front"/>
    <origin rpy="0 0 0" xyz="0.06 0 0.02"/>
  </joint>
  <link name="ir_front_left">
    <visual>
      <geometry>
        <cylinder length="0.02" radius="0.005"/>
      </geometry>
      <material name="Red"/>
    </visual>
    <collision>
      <geometry>
        <cylinder length="0.02" radius="0.005"/>
      </geometry>
    </collision>
  </link>
  <joint name="ir_front_left_joint" type="fixed">
    <parent link="base_link"/>
    <child link="ir_front_left"/>
    <origin rpy="0 0 0.785" xyz="0.05 0.03 0.02"/>
  </joint>
  <link name="ir_front_right">
    <visual>
      <geometry>
        <cylinder length="0.02" radius="0.005"/>
      </geometry>
      <material name="Red"/>
    </visual>
    <collision>
      <geometry>
        <cylinder length="0.02" radius="0.005"/>
      </geometry>
    </collision>
  </link>
  <joint name="ir_front_right_joint" type="fixed">
    <parent link="base_link"/>
    <child link="ir_front_right"/>
    <origin rpy="0 0 -0.785" xyz="0.05 -0.03 0.02"/>
  </joint>
  <link name="ir_left">
    <visual>
      <geometry>
        <cylinder length="0.02" radius="0.005"/>
      </geometry>
      <material name="Red"/>
    </visual>
    <collision>
      <geometry>
        <cylinder length="0.02" radius="0.005"/>
      </geometry>
    </collision>
  </link>
  <joint name="ir_left_joint" type="fixed">
    <parent link="base_link"/>
    <child link="ir_left"/>
    <origin rpy="0 0 1.57" xyz="0 0.05 0.02"/>
  </joint>
  <link name="ir_right">
    <visual>
      <geometry>
        <cylinder length="0.02" radius="0.005"/>
      </geometry>
      <material name="Red"/>
    </visual>
    <collision>
      <geometry>
        <cylinder length="0.02" radius="0.005"/>
      </geometry>
    </collision>
  </link>
  <joint name="ir_right_joint" type="fixed">
    <parent link="base_link"/>
    <child link="ir_right"/>
    <origin rpy="0 0 -1.57" xyz="0 -0.05 0.02"/>
  </joint>
  <!-- ========= Diff Drive Plugin ========= -->
  <gazebo>
    <plugin filename="libgazebo_ros_diff_drive.so" name="diff_drive_controller">
      <ros>
        <namespace>/</namespace>
        <remapping>cmd_vel:=/cmd_vel</remapping>
      </ros>
      <updateRate>100.0</updateRate>
      <wheelSeparation>0.08</wheelSeparation>
      <wheelDiameter>0.06</wheelDiameter>
      <leftJoint>wheel_left</leftJoint>
      <rightJoint>wheel_right</rightJoint>
      <robotBaseFrame>base_link</robotBaseFrame>
    </plugin>
  </gazebo>
  <inertial>
    <mass value="0.5"/>
    <inertia ixx="0.001" ixy="0.0" ixz="0.0" iyy="0.001" iyz="0.0" izz="0.001"/>
  </inertial>
</robot>
